<?xml version="1.0" encoding="utf-8"?>
<robot
  name="carwheel">
  <link name="body">
    <inertial>
      <origin
        xyz="0 0 0"
        rpy="0 0 0" />
      <mass
        value="3.94900947494756" />
      <inertia
        ixx="0.00773393995430153"
        ixy="0.0"
        ixz="0.0"
        iyy="0.0207892752411963"
        iyz="0.0"
        izz="0.0275077758026154" />
    </inertial>
    <visual>
      <origin
        xyz="0 0 0"
        rpy="0 0 0" />
      <geometry>
        <mesh filename="package://oatmeal_gazebo/simulation/models/carwheel/meshes/body.STL" />
      </geometry>
      <material name="">
        <color rgba="1 1 1 1" />
      </material>
    </visual>
    <collision>
      <origin
        xyz="0 0 0"
        rpy="0 0 0" />
      <geometry>
        <mesh filename="package://oatmeal_gazebo/simulation/models/carwheel/meshes/body.STL" />
      </geometry>
    </collision>
  </link>
  <gazebo reference="body">
    <material>Gazebo/Orange</material>
  </gazebo>
  <link name="FR">
    <inertial>
      <origin
        xyz="0 0 0"
        rpy="1.5707963267948966 0 0" />
      <mass
        value="0.0482548631591392" />
      <inertia
        ixx="1.97040691233152E-05"
        ixy="0.0"
        ixz="0.0"
        iyy="3.86038905273114E-05"
        iyz="0.0"
        izz="1.97040691233152E-05" />
    </inertial>
    <visual>
      <origin
        xyz="0 0 0"
        rpy="1.5707963267948966 0 0" />
      <geometry>
        <cylinder radius="0.05" length="0.01"/>
        <!-- <mesh filename="package://oatmeal_gazebo/simulation/models/carwheel/meshes/FR.STL" /> -->
      </geometry>
      <material name="">
        <color rgba="1 1 1 1" />
      </material>
    </visual>
    <collision>
      <origin
        xyz="0 0 0"
        rpy="1.5707963267948966 0 0" />
      <geometry>
        <cylinder radius="0.051" length="0.0001"/>
      </geometry>
    </collision>
  </link>
  <gazebo reference="FR">
    <material>Gazebo/Blue</material>
  </gazebo>
  <joint
    name="Joint_FR"
    type="revolute">
    <origin
      xyz="0.095 -0.08 0"
      rpy="0 0 0" />
    <parent
      link="body" />
    <child
      link="FR" />
    <axis
      xyz="0 1 0" />
    <limit
      lower="-1000000"
      upper="1000000"
      effort="30"
      velocity="20" />
  </joint>
  <gazebo reference="Joint_FR">
    <kp>1.0</kp>
    <kd>1.0</kd>
    <stopCfm>0.8</stopCfm>
    <stopErp>0.5</stopErp>
    <provideFeedback>true</provideFeedback>
    <!-- Important para to enable ft sensor-->
    <disableFixedJointLumping>true</disableFixedJointLumping>
    <implicitSpringDamper>true</implicitSpringDamper>
    <fudgeFactor>0.0</fudgeFactor>
  </gazebo>
  <link name="FL">
    <inertial>
      <origin
        xyz="0 0 0"
        rpy="0 0 0" />
      <mass
        value="0.0482548631591393" />
      <inertia
        ixx="1.97040691233152E-05"
        ixy="0.0"
        ixz="0.0"
        iyy="3.86038905273114E-05"
        iyz="0.0"
        izz="1.97040691233152E-05" />
    </inertial>
    <visual>
      <origin
        xyz="0 0 0"
        rpy="1.5707963267948966 0 0" />
      <geometry>
        <cylinder radius="0.05" length="0.01"/>
        <!-- <mesh filename="package://oatmeal_gazebo/simulation/models/carwheel/meshes/FL.STL" /> -->
      </geometry>
      <material name="">
        <color rgba="1 1 1 1" />
      </material>
    </visual>
    <collision>
      <origin
        xyz="0 0 0"
        rpy="1.5707963267948966 0 0" />
      <geometry>
        <cylinder radius="0.051" length="0.0001"/>
      </geometry>
    </collision>
  </link>
  <gazebo reference="FL">
    <material>Gazebo/Green</material>
  </gazebo>
  <joint name="Joint_FL"
    type="revolute">
    <origin
      xyz="0.095 0.08 0"
      rpy="0 0 0" />
    <parent
      link="body" />
    <child
      link="FL" />
    <axis
      xyz="0 1 0" />
    <limit
      lower="-1000000"
      upper="1000000"
      effort="30"
      velocity="20" />
  </joint>
  <gazebo reference="Joint_FL">
    <kp>1.0</kp>
    <kd>1.0</kd>
    <stopCfm>0.8</stopCfm>
    <stopErp>0.5</stopErp>
    <provideFeedback>true</provideFeedback>
    <!-- Important para to enable ft sensor-->
    <disableFixedJointLumping>true</disableFixedJointLumping>
    <implicitSpringDamper>true</implicitSpringDamper>
    <fudgeFactor>0.0</fudgeFactor>
  </gazebo>
  <link name="HR">
    <inertial>
      <origin
        xyz="0 0 0"
        rpy="0 0 0" />
      <mass
        value="0.0482548631591392" />
      <inertia
        ixx="1.97040691233152E-05"
        ixy="0.0"
        ixz="0.0"
        iyy="3.86038905273114E-05"
        iyz="0.0"
        izz="1.97040691233152E-05" />
    </inertial>
    <visual>
      <origin
        xyz="0 0 0"
        rpy="1.5707963267948966 0 0" />
      <geometry>
        <cylinder radius="0.05" length="0.01"/>/
        <!-- <mesh filename="package://oatmeal_gazebo/simulation/models/carwheel/meshes/HR.STL" /> -->
      </geometry>
      <material name="">
        <color rgba="1 1 1 1" />
      </material>
    </visual>
    <collision>
      <origin
        xyz="0 0 0"
        rpy="1.5707963267948966 0 0" />
      <geometry>
        <cylinder radius="0.051" length="0.0001"/>
      </geometry>
    </collision>
  </link>
  <gazebo reference="HR">
    <material>Gazebo/Yellow</material>
  </gazebo>
  <joint name="Joint_HR"
    type="revolute">
    <origin
      xyz="-0.115 -0.08 0"
      rpy="0 0 0" />
    <parent
      link="body" />
    <child
      link="HR" />
    <axis
      xyz="0 1 0" />
    <limit
      lower="-1000000"
      upper="1000000"
      effort="30"
      velocity="20" />
  </joint>
  <gazebo reference="Joint_HR">
    <kp>1.0</kp>
    <kd>1.0</kd>
    <stopCfm>0.8</stopCfm>
    <stopErp>0.5</stopErp>
    <provideFeedback>true</provideFeedback>
    <!-- Important para to enable ft sensor-->
    <disableFixedJointLumping>true</disableFixedJointLumping>
    <implicitSpringDamper>true</implicitSpringDamper>
    <fudgeFactor>0.0</fudgeFactor>
  </gazebo>
  <link name="HL">
    <inertial>
      <origin
        xyz="0 0 0"
        rpy="1.5707963267948966 0 0" />
      <mass
        value="0.0482548631591393" />
      <inertia
        ixx="1.97040691233152E-05"
        ixy="0.0"
        ixz="0.0"
        iyy="3.86038905273114E-05"
        iyz="0.0"
        izz="1.97040691233152E-05" />
    </inertial>
    <visual>
      <origin
        xyz="0 0 0"
        rpy="1.5707963267948966 0 0" />
      <geometry>
        <cylinder radius="0.05" length="0.01"/>
      </geometry>
      <material name="">
        <color rgba="1 1 1 1" />
      </material>
    </visual>
    <collision>
      <origin
        xyz="0 0 0"
        rpy="1.5707963267948966 0 0" />
      <geometry>
        <cylinder radius="0.051" length="0.0001"/>
      </geometry>
    </collision>
  </link>
  <gazebo reference="HL">
    <material>Gazebo/Red</material>
  </gazebo>
  <joint name="Joint_HL"
    type="revolute">
    <origin
      xyz="-0.115 0.08 0"
      rpy="0 0 0" />
    <parent
      link="body" />
    <child
      link="HL" />
    <axis
      xyz="0 1 0" />
    <limit
      lower="-1000000"
      upper="1000000"
      effort="30"
      velocity="20" />
  </joint>
  <gazebo reference="Joint_HL">
    <kp>1.0</kp>
    <kd>1.0</kd>
    <stopCfm>0.8</stopCfm>
    <stopErp>0.5</stopErp>
    <provideFeedback>true</provideFeedback>
    <!-- Important para to enable ft sensor-->
    <disableFixedJointLumping>true</disableFixedJointLumping>
    <implicitSpringDamper>true</implicitSpringDamper>
    <fudgeFactor>0.0</fudgeFactor>
  </gazebo>
</robot>
