Skip to content
Search or jump to…
Pull requests
Issues
Marketplace
Explore

@simanxu
simanxu
/
robot_learning
Public
Code
Issues
Pull requests
Actions
Projects
Wiki
Security
Insights
Settings
robot_learning/src/carwheel/urdf/carwheel.urdf

simanxu Update
Latest commit ff8574e on May 18, 2021
 History
 1 contributor
Executable File  328 lines (328 sloc)  8.17 KB

<?xml version="1.0" encoding="utf-8"?>
<!-- This URDF was automatically created by SolidWorks to URDF Exporter! Originally created by Stephen Brawner (brawner@gmail.com)
     Commit Version: 1.6.0-1-g15f4949  Build Version: 1.6.7594.29634
     For more information, please see http://wiki.ros.org/sw_urdf_exporter -->
<robot
  name="carwheel">
  <!-- Add a fixed base of robot -->
  <!-- <link name="world"/>
  <joint name="fixed" type="fixed">
    <parent link="world"/>
    <child link="body"/>
  </joint> -->
  <link name="body">
    <inertial>
      <origin
        xyz="0.0 0.0 1.2"
        rpy="0 0 0" />
      <mass
        value="3.94900947494756" />
      <inertia
        ixx="0.00773393995430153"
        ixy="3.9979040259175E-10"
        ixz="2.54923494802793E-06"
        iyy="0.0207892752411963"
        iyz="-9.86488895643997E-11"
        izz="0.0275077758026154" />
    </inertial>
    <visual>
      <origin
        xyz="0 0 0"
        rpy="0 0 0" />
      <geometry>
        <mesh
          filename="package://carwheel/meshes/body.STL" />
      </geometry>
      <material
        name="aluminum">
        <color
          rgba="0.898039215686275 0.917647058823529 0.929411764705882 1" />
      </material>
    </visual>
    <collision>
      <origin
        xyz="0 0 0"
        rpy="0 0 0" />
      <geometry>
        <mesh
          filename="package://carwheel/meshes/body.STL" />
      </geometry>
    </collision>
  </link>
  <gazebo reference="body">
    <material>Gazebo/Orange</material>
  </gazebo>
  <link name="FR">
    <inertial>
      <origin
        xyz="0 0 0"
        rpy="0 0 0" />
      <mass
        value="0.0482548631591392" />
      <inertia
        ixx="1.97040691233152E-05"
        ixy="1.84339936206638E-38"
        ixz="-4.06575814682064E-22"
        iyy="3.86038905273114E-05"
        iyz="-6.23911102134557E-38"
        izz="1.97040691233152E-05" />
    </inertial>
    <visual>
      <origin
        xyz="0 0 0"
        rpy="1.5707963267948966 0 0" />
      <geometry>
        <cylinder radius="0.05" length="0.01"/>
      </geometry>
      <material
        name="">
        <color
          rgba="1 1 1 1" />
      </material>
    </visual>
    <collision>
      <origin
        xyz="0 0 0"
        rpy="1.5707963267948966 0 0" />
      <geometry>
        <cylinder radius="0.05" length="0.01"/>
      </geometry>
    </collision>
  </link>
  <gazebo reference="FR">
    <material>Gazebo/Blue</material>
  </gazebo>
  <joint
    name="Joint_FR"
    type="revolute">
    <origin
      xyz="0.095 -0.08 0"
      rpy="0 0 0" />
    <parent
      link="body" />
    <child
      link="FR" />
    <axis
      xyz="0 1 0" />
    <limit
      lower="-1000000000"
      upper="1000000000"
      effort="0"
      velocity="0" />
  </joint>
  <gazebo reference="Joint_FR">
    <kp>1.0</kp>
    <kd>1.0</kd>
    <stopCfm>0.8</stopCfm>
    <stopErp>0.5</stopErp>
    <provideFeedback>true</provideFeedback>
    <!-- Important para to enable ft sensor-->
    <disableFixedJointLumping>true</disableFixedJointLumping>
    <implicitSpringDamper>true</implicitSpringDamper>
    <fudgeFactor>0.0</fudgeFactor>
  </gazebo>
  <link name="FL">
    <inertial>
      <origin
        xyz="0 0 0"
        rpy="0 0 0" />
      <mass
        value="0.0482548631591393" />
      <inertia
        ixx="1.97040691233152E-05"
        ixy="1.76324152623343E-38"
        ixz="-2.82118644197349E-37"
        iyy="3.86038905273114E-05"
        iyz="-1.10202595389589E-38"
        izz="1.97040691233152E-05" />
    </inertial>
    <visual>
      <origin
        xyz="0 0 0"
        rpy="1.5707963267948966 0 0" />
      <geometry>
        <cylinder radius="0.05" length="0.01"/>
      </geometry>
      <material
        name="">
        <color
          rgba="1 1 1 1" />
      </material>
    </visual>
    <collision>
      <origin
        xyz="0 0 0"
        rpy="1.5707963267948966 0 0" />
      <geometry>
        <cylinder radius="0.05" length="0.01"/>
      </geometry>
    </collision>
  </link>
  <gazebo reference="FL">
    <material>Gazebo/Green</material>
  </gazebo>
  <joint name="Joint_FL"
    type="revolute">
    <origin
      xyz="0.095 0.08 0"
      rpy="0 0 0" />
    <parent
      link="body" />
    <child
      link="FL" />
    <axis
      xyz="0 1 0" />
    <limit
      lower="-1000000000"
      upper="1000000000"
      effort="0"
      velocity="0" />
  </joint>
  <gazebo reference="Joint_FL">
    <kp>1.0</kp>
    <kd>1.0</kd>
    <stopCfm>0.8</stopCfm>
    <stopErp>0.5</stopErp>
    <provideFeedback>true</provideFeedback>
    <!-- Important para to enable ft sensor-->
    <disableFixedJointLumping>true</disableFixedJointLumping>
    <implicitSpringDamper>true</implicitSpringDamper>
    <fudgeFactor>0.0</fudgeFactor>
  </gazebo>
  <link name="HR">
    <inertial>
      <origin
        xyz="0 0 0"
        rpy="0 0 0" />
      <mass
        value="0.0482548631591392" />
      <inertia
        ixx="1.97040691233152E-05"
        ixy="1.35525271560688E-22"
        ixz="5.84452733605467E-22"
        iyy="3.86038905273114E-05"
        iyz="1.35525271560688E-22"
        izz="1.97040691233152E-05" />
    </inertial>
    <visual>
      <origin
        xyz="0 0 0"
        rpy="1.5707963267948966 0 0" />
      <geometry>
        <cylinder radius="0.05" length="0.01"/>
      </geometry>
      <material
        name="">
        <color
          rgba="1 1 1 1" />
      </material>
    </visual>
    <collision>
      <origin
        xyz="0 0 0"
        rpy="1.5707963267948966 0 0" />
      <geometry>
        <cylinder radius="0.05" length="0.01"/>
      </geometry>
    </collision>
  </link>
  <gazebo reference="HR">
    <material>Gazebo/Yellow</material>
  </gazebo>
  <joint name="Joint_HR"
    type="revolute">
    <origin
      xyz="-0.115 -0.08 0"
      rpy="0 0 0" />
    <parent
      link="body" />
    <child
      link="HR" />
    <axis
      xyz="0 1 0" />
    <limit
      lower="-1000000000"
      upper="1000000000"
      effort="0"
      velocity="0" />
  </joint>
  <gazebo reference="Joint_HR">
    <kp>1.0</kp>
    <kd>1.0</kd>
    <stopCfm>0.8</stopCfm>
    <stopErp>0.5</stopErp>
    <provideFeedback>true</provideFeedback>
    <!-- Important para to enable ft sensor-->
    <disableFixedJointLumping>true</disableFixedJointLumping>
    <implicitSpringDamper>true</implicitSpringDamper>
    <fudgeFactor>0.0</fudgeFactor>
  </gazebo>
  <link name="HL">
    <inertial>
      <origin
        xyz="0 0 0"
        rpy="0 0 0" />
      <mass
        value="0.0482548631591393" />
      <inertia
        ixx="1.97040691233152E-05"
        ixy="-1.76324152623343E-38"
        ixz="-2.82118644197349E-37"
        iyy="3.86038905273114E-05"
        iyz="-1.10202595389589E-38"
        izz="1.97040691233152E-05" />
    </inertial>
    <visual>
      <origin
        xyz="0 0 0"
        rpy="1.5707963267948966 0 0" />
      <geometry>
        <cylinder radius="0.05" length="0.01"/>
      </geometry>
      <material
        name="">
        <color
          rgba="1 1 1 1" />
      </material>
    </visual>
    <collision>
      <origin
        xyz="0 0 0"
        rpy="1.5707963267948966 0 0" />
      <geometry>
        <cylinder radius="0.05" length="0.01"/>
      </geometry>
    </collision>
  </link>
  <gazebo reference="HL">
    <material>Gazebo/Red</material>
  </gazebo>
  <joint name="Joint_HL"
    type="revolute">
    <origin
      xyz="-0.115 0.08 0"
      rpy="0 0 0" />
    <parent
      link="body" />
    <child
      link="HL" />
    <axis
      xyz="0 1 0" />
    <limit
      lower="-1000000000"
      upper="1000000000"
      effort="0"
      velocity="0" />
  </joint>
  <gazebo reference="Joint_HL">
    <kp>1.0</kp>
    <kd>1.0</kd>
    <stopCfm>0.8</stopCfm>
    <stopErp>0.5</stopErp>
    <provideFeedback>true</provideFeedback>
    <!-- Important para to enable ft sensor-->
    <disableFixedJointLumping>true</disableFixedJointLumping>
    <implicitSpringDamper>true</implicitSpringDamper>
    <fudgeFactor>0.0</fudgeFactor>
  </gazebo>
</robot>
© 2022 GitHub, Inc.
Terms
Privacy
Security
Status
Docs
Contact GitHub
Pricing
API
Training
Blog
About
Loading complete
